Workbook

Sheet Guide
A1: Prairie Ridge Community Hospital: Scenario Model
A2: Illustrative case study model. Prairie Ridge is a fictional hospital; all hospital figures are assumptions. $ millions unless noted.
A4: Purpose | B4: Compares three FY2028 strategies for a 25-bed rural hospital: A) hold as a Critical Access Hospital, B) convert to a Rural Emergency Hospital (REH), C) transform as a CAH (recommended).
A5: How to use | B5: Change blue cells on the Inputs sheet (and the blue cells on Initiatives, Sensitivity and AI_ROI). Every other number recalculates.
A6: Colour legend | B6: Blue text = hardcoded input. Black = formula. Green = link to another sheet. Yellow fill = key assumption to test first.
A7: Inputs | B7: Every assumption in one place, with its source or a note saying it is an illustrative assumption.
A8: Baseline | B8: FY2026 revenue, expenses, margin and payer mix.
A9: Headwinds | B9: Revenue lost to the Medicaid work requirements, ACA subsidy expiration and state Medicaid financing pressure, plus the loss by payer.
A10: Initiatives | B10: The six transformation initiatives with gains, new costs, AI tooling and operating tie-outs.
A11: Scenarios | B11: Side-by-side FY2028 revenue, expenses, result, margin and FTEs, with a tie-out to the case study.
A12: Sensitivity | B12: Tornado table (each assumption moved alone) and stress cases against the -3.0% REH trigger.
A13: AI_ROI | B13: Tooling cost against attributable benefit for three AI tools, with low, base and high cases and a break-even point.
A14: Sources | B14: REH monthly facility payment: CMS MLN Fact Sheet MLN2259384 (Dec 2025), https://www.cms.gov/files/document/mln2259384-rural-emergency-hospitals.pdf. Dispute-fee and batching changes: Jones Day, 8 Jun 2026, https://www.jonesday.com/en/insights/2026/06/new-rule-amends-no-surprises-act-dispute-process-for-outofnetwork-health-care-payments. Everything else is an illustrative assumption.
A15: Rounding | B15: Headwinds, the Medicare outpatient shift and the REH payment are rounded to $0.01M so the model ties to the case study figures.

Sheet Inputs
A1: Inputs
A2: Blue = input. Yellow = key assumption. Every value is an illustrative assumption unless the note cites a source.
A3: Assumption | B3: Value | C3: Unit | D3: Source or note
A4: Baseline revenue, FY2026
A5: Inpatient and swing-bed revenue | B5: 6.1 | C5: $M | D5: Illustrative assumption
A6: Emergency department revenue | B6: 9.4 | C6: $M | D6: Illustrative assumption
A7: Outpatient and ancillary revenue | B7: 13.7 | C7: $M | D7: Illustrative assumption
A8: Other operating revenue | B8: 0.8 | C8: $M | D8: Illustrative assumption
A9: Baseline expenses, FY2026
A10: Salaries and benefits | B10: 17.6 | C10: $M | D10: Illustrative assumption
A11: Supplies and pharmacy | B11: 4.3 | C11: $M | D11: Illustrative assumption
A12: Purchased services and contracted physicians | B12: 5.1 | C12: $M | D12: Illustrative assumption
A13: Depreciation and interest | B13: 1.8 | C13: $M | D13: Illustrative assumption
A14: Other expenses | B14: 2.6 | C14: $M | D14: Illustrative assumption
A15: Payer mix (share of net patient service revenue)
A16: Medicare | B16: 0.48 | C16: % | D16: Illustrative assumption
A17: Medicaid | B17: 0.17 | C17: % | D17: Illustrative assumption
A18: Commercial | B18: 0.27 | C18: % | D18: Illustrative assumption
A19: Self-pay | B19: 0.08 | C19: % | D19: Illustrative assumption; shares must sum to 100%
A20: Operations
A21: Full-time equivalents (FTEs) | B21: 212 | C21: FTEs | D21: Illustrative assumption
A22: ED visits per year | B22: 11400 | C22: visits | D22: Illustrative assumption
A23: Inpatient admissions per year | B23: 580 | C23: admissions | D23: Illustrative assumption
A24: Average daily inpatient census | B24: 6.2 | C24: patients | D24: Illustrative assumption
A25: Federal policy headwinds
A26: Expansion adults as share of Medicaid revenue | B26: 0.35 | C26: % | D26: Illustrative assumption
A27: Expansion adults losing coverage after work requirements | B27: 0.18 | C27: % | D27: Illustrative assumption; work requirements due by Jan 1, 2027 under OBBBA
A28: Marketplace plans as share of commercial revenue | B28: 0.12 | C28: % | D28: Illustrative assumption
A29: Marketplace enrollees who drop coverage | B29: 0.25 | C29: % | D29: Illustrative assumption; enhanced premium tax credits expired Dec 31, 2025
A30: State supplemental Medicaid payment cut (share of Medicaid revenue) | B30: 0.06 | C30: % | D30: Illustrative assumption; provider-tax reductions begin Oct 1, 2027
A31: Rural Emergency Hospital (REH) inputs
A32: REH monthly facility payment, CY2026 | B32: 295051.54 | C32: $ | D32: Source: CMS MLN Fact Sheet MLN2259384, Dec 2025 (after sequestration)
A33: Months of facility payment per year | B33: 12 | C33: months | D33: CMS pays in 12 monthly installments
A34: Medicare share of ED and outpatient revenue | B34: 0.48 | C34: % | D34: Illustrative assumption
A35: Medicare outpatient payment shift under REH (OPPS + 5% vs cost-based) | B35: 0.06 | C35: % | D35: Illustrative assumption; shift is a reduction
A36: Observation revenue retained after conversion | B36: 0.9 | C36: $M | D36: Illustrative assumption
A37: Inpatient costs removed after conversion | B37: 5.4 | C37: $M | D37: Illustrative assumption
A38: FTEs removed after conversion | B38: 38 | C38: FTEs | D38: Illustrative assumption
A39: Scenario C and operating inputs
A40: Net FTEs added in Scenario C | B40: 10 | C40: FTEs | D40: Illustrative assumption
...

Sheet Baseline
A1: Baseline: FY2026
A2: $ millions. Links to Inputs.
A4: Revenue ($M) | B4: FY2026
A5: Inpatient and swing-bed | B5: =Inputs!$B$5 -> 6.1
A6: Emergency department | B6: =Inputs!$B$6 -> 9.4
A7: Outpatient and ancillary | B7: =Inputs!$B$7 -> 13.7
A8: Net patient service revenue | B8: =SUM(B5:B7) -> 29.2
A9: Other operating revenue | B9: =Inputs!$B$8 -> 0.8
A10: Total operating revenue | B10: =B8+B9 -> 30
A12: Expenses ($M) | B12: FY2026
A13: Salaries and benefits | B13: =Inputs!$B$10 -> 17.6
A14: Supplies and pharmacy | B14: =Inputs!$B$11 -> 4.3
A15: Purchased services and contracted physicians | B15: =Inputs!$B$12 -> 5.1
A16: Depreciation and interest | B16: =Inputs!$B$13 -> 1.8
A17: Other | B17: =Inputs!$B$14 -> 2.6
A18: Total operating expenses | B18: =SUM(B13:B17) -> 31.4
A20: Operating result ($M) | B20: =B10-B18 -> -1.4
A21: Operating margin | B21: =B20/B10 -> -0.046666667
A23: Payer mix | B23: Share of net patient revenue | C23: Revenue ($M)
A24: Medicare | B24: =Inputs!$B$16 -> 0.48 | C24: =ROUND(B24*$B$8,1) -> 14
A25: Medicaid | B25: =Inputs!$B$17 -> 0.17 | C25: =ROUND(B25*$B$8,1) -> 5
A26: Commercial | B26: =Inputs!$B$18 -> 0.27 | C26: =ROUND(B26*$B$8,1) -> 7.9
A27: Self-pay | B27: =Inputs!$B$19 -> 0.08 | C27: =ROUND(B27*$B$8,1) -> 2.3
A28: Total | B28: =SUM(B24:B27) -> 1 | C28: =SUM(C24:C27) -> 29.2
A29: Check: payer revenue ties to net patient service revenue | C29: =IF(ABS(C28-B8)<0.051,"OK","Review") -> OK
A30: Payer revenue is rounded to $0.1M to match the case study.

Sheet Headwinds
A1: Federal policy headwinds, FY2028
A2: $ millions. Each impact is rounded to $0.01M.
A4: Headwind | B4: Revenue exposed ($M) | C4: Rate | D4: Annual revenue impact ($M) | E4: Starts
A5: Medicaid work requirements | B5: =Baseline!$C$25*Inputs!$B$26 -> 1.75 | C5: =Inputs!$B$27 -> 0.18 | D5: =-ROUND(B5*C5,2) -> -0.32 | E5: Jan 1, 2027
A6: Marketplace subsidy expiration | B6: =Baseline!$C$26*Inputs!$B$28 -> 0.948 | C6: =Inputs!$B$29 -> 0.25 | D6: =-ROUND(B6*C6,2) -> -0.24 | E6: Jan 1, 2026
A7: State Medicaid financing pressure | B7: =Baseline!$C$25 -> 5 | C7: =Inputs!$B$30 -> 0.06 | D7: =-ROUND(B7*C7,2) -> -0.3 | E7: FY2028
A8: Total | D8: =SUM(D5:D7) -> -0.86
A9: Headwinds as share of operating revenue | D9: =-D8/Baseline!$B$10 -> 0.028666667
A11: Loss by payer | B11: Share of net patient revenue | C11: Revenue lost ($M) | D11: Share of loss
A12: Medicare | B12: =Baseline!B24 -> 0.48 | C12: 0 | D12: =IF($C$16=0,0,C12/$C$16) -> 0
A13: Medicaid | B13: =Baseline!B25 -> 0.17 | C13: =-(D5+D7) -> 0.62 | D13: =IF($C$16=0,0,C13/$C$16) -> 0.72093023
A14: Commercial | B14: =Baseline!B26 -> 0.27 | C14: =-D6 -> 0.24 | D14: =IF($C$16=0,0,C14/$C$16) -> 0.27906977
A15: Self-pay | B15: =Baseline!B27 -> 0.08 | C15: 0 | D15: =IF($C$16=0,0,C15/$C$16) -> 0
A16: Total | B16: =SUM(B12:B15) -> 1 | C16: =SUM(C12:C15) -> 0.86 | D16: =SUM(D12:D15) -> 1
A17: Medicare and self-pay carry no modeled loss (assumption, blue zeros).

Sheet Initiatives
A1: Scenario C: six transformation initiatives
A2: Run-rate by FY2028, $ millions. Blue = input.
A4: # | B4: Initiative | C4: Type | D4: Gain or savings ($M) | E4: New annual cost ($M) | F4: Net ($M) | G4: AI tooling inside new cost ($M) | H4: AI-tooled? | I4: Policy hook
A5: 1 | B5: Primary care and behavioral health clinic expansion | C5: Revenue | D5: 1.2 | E5: 0.8 | F5: =D5-E5 -> 0.4 | G5: 0.1 | H5: Y | I5: RHTP access and workforce priorities
A6: 2 | B6: Tele-emergency and telepsychiatry | C6: Revenue | D6: 0.5 | E6: 0.4 | F6: =D6-E6 -> 0.1 | G6: 0.1 | H6: Y | I6: RHTP technology priorities
A7: 3 | B7: Swing-bed utilization program | C7: Revenue | D7: 0.6 | E7: 0.1 | F7: =D7-E7 -> 0.5 | G7: 0 | H7: N | I7: CAH cost-based payment
A8: 4 | B8: Revenue cycle upgrade and No Surprises Act dispute desk | C8: Revenue | D8: 0.35 | E8: 0.2 | F8: =D8-E8 -> 0.15 | G8: 0.1 | H8: Y | I8: May 2026 IDR rule: $15 fee, 50-line batching
A9: 5 | B9: Supply chain and purchased-services renegotiation | C9: Savings | D9: 0.8 | E9: 0 | F9: =D9-E9 -> 0.8 | G9: 0 | H9: N | I9: Margin protection
A10: 6 | B10: Retention program and float pool to cut agency labor | C10: Savings | D10: 0.6 | E10: 0 | F10: =D10-E10 -> 0.6 | G10: 0 | H10: N | I10: Workforce stability
B11: Total | D11: =SUM(D5:D10) -> 4.05 | E11: =SUM(E5:E10) -> 1.5 | F11: =SUM(F5:F10) -> 2.55 | G11: =SUM(G5:G10) -> 0.3
B13: Summary | D13: Value
B14: Revenue-type gains ($M) | D14: =SUMIF($C$5:$C$10,"Revenue",$D$5:$D$10) -> 2.65
B15: Cost savings ($M) | D15: =SUMIF($C$5:$C$10,"Savings",$D$5:$D$10) -> 1.4
B16: New annual cost ($M) | D16: =E11 -> 1.5
B17: Gross gain in AI-tooled initiatives ($M) | D17: =SUMIF($H$5:$H$10,"Y",$D$5:$D$10) -> 2.05
B18: AI-tooled share of gross gain | D18: =D17/D11 -> 0.50617284
B19: AI tooling as share of new cost | D19: =G11/E11 -> 0.2
B21: Operating checks | D21: Value
B22: ED transfers per year, baseline | D22: =Inputs!$B$22*Inputs!$B$41 -> 684
B23: ED transfers per year, target | D23: =Inputs!$B$22*Inputs!$B$42 -> 513
B24: Transfers avoided per year | D24: =D22-D23 -> 171
B25: One-time cash from fewer A/R days ($M) | D25: =Baseline!$B$8/365*(Inputs!$B$43-Inputs!$B$44) -> 0.96
B26: Dispute-desk recoveries from claim count ($M) | D26: =Inputs!$B$45*Inputs!$B$46/1000000 -> 0.3502
B27: Difference vs initiative 4 gain ($M) | D27: =D8-D26 -> -0.0002
B28: Expansion-adult Medicaid revenue ($M) | D28: =Headwinds!$B$5 -> 1.75
B29: Disenrollment rate with outreach (option) | D29: 0.14
B30: Coverage-outreach benefit ($M, outside base plan) | D30: =D28*(Inputs!$B$27-D29) -> 0.07
B32: Type must be Revenue or Savings; SUMIF formulas use it. AI tooling and AI-tooled flags are assumptions (initiatives 5 and 6 carry no separate AI budget).

Sheet Scenarios
A1: FY2028 scenario comparison
A2: $ millions, steady state. Headwinds apply to all three; expenses held at FY2026 dollars.
A4: Line ($M) | B4: A: Hold as CAH | C4: B: Convert to REH | D4: C: CAH transformation
A5: Baseline operating revenue | B5: =Baseline!$B$10 -> 30 | C5: =Baseline!$B$10 -> 30 | D5: =Baseline!$B$10 -> 30
A6: Federal headwinds | B6: =Headwinds!$D$8 -> -0.86 | C6: =Headwinds!$D$8 -> -0.86 | D6: =Headwinds!$D$8 -> -0.86
A7: Inpatient and swing revenue lost | B7: 0 | C7: =-Inputs!$B$5 -> -6.1 | D7: 0
A8: Observation stays retained | B8: 0 | C8: =Inputs!$B$36 -> 0.9 | D8: 0
A9: Medicare outpatient shift to OPPS | B9: 0 | C9: =-ROUND(Inputs!$B$34*(Inputs!$B$6+Inputs!$B$7)*Inputs!$B$35,2) -> -0.67 | D9: 0
A10: REH monthly facility payment | B10: 0 | C10: =ROUND(Inputs!$B$32*Inputs!$B$33/1000000,2) -> 3.54 | D10: 0
A11: Initiative revenue gains | B11: 0 | C11: 0 | D11: =Initiatives!$D$14 -> 2.65
A12: Operating revenue | B12: =SUM(B5:B11) -> 29.14 | C12: =SUM(C5:C11) -> 26.81 | D12: =SUM(D5:D11) -> 31.79
A14: Baseline operating expenses | B14: =Baseline!$B$18 -> 31.4 | C14: =Baseline!$B$18 -> 31.4 | D14: =Baseline!$B$18 -> 31.4
A15: Inpatient costs removed | B15: 0 | C15: =-Inputs!$B$37 -> -5.4 | D15: 0
A16: New program costs | B16: 0 | C16: 0 | D16: =Initiatives!$D$16 -> 1.5
A17: Cost savings | B17: 0 | C17: 0 | D17: =-Initiatives!$D$15 -> -1.4
A18: Operating expenses | B18: =SUM(B14:B17) -> 31.4 | C18: =SUM(C14:C17) -> 26 | D18: =SUM(D14:D17) -> 31.5
A20: Operating result ($M) | B20: =B12-B18 -> -2.26 | C20: =C12-C18 -> 0.81 | D20: =D12-D18 -> 0.29
A21: Operating margin | B21: =B20/B12 -> -0.077556623 | C21: =C20/C12 -> 0.030212607 | D21: =D20/D12 -> 0.0091223655
A22: Below REH trigger? | B22: =IF(B21<Inputs!$B$47,"Breach","OK") -> Breach | C22: =IF(C21<Inputs!$B$47,"Breach","OK") -> OK | D22: =IF(D21<Inputs!$B$47,"Breach","OK") -> OK
A23: FTEs | B23: =Inputs!$B$21 -> 212 | C23: =Inputs!$B$21-Inputs!$B$38 -> 174 | D23: =Inputs!$B$21+Inputs!$B$40 -> 222
A25: Decision metrics
A26: Net revenue effect of REH conversion, before headwinds ($M) | C26: =SUM(C7:C10) -> -2.33
A27: REH result after revenue changes, before cost cuts ($M) | C27: =C12-C14 -> -4.59
A28: Scenario C result improvement vs Scenario A ($M) | D28: =D20-B20 -> 2.55
A30: Tie-out to case study | B30: A | C30: B | D30: C
A31: Case-study margin (typed from the case study) | B31: -0.078 | C31: 0.03 | D31: 0.009
A32: Model margin, rounded to 0.1% | B32: =ROUND(B21,3) -> -0.078 | C32: =ROUND(C21,3) -> 0.03 | D32: =ROUND(D21,3) -> 0.009
A33: Status | B33: =IF(B32=B31,"OK","CHECK") -> OK | C33: =IF(C32=C31,"OK","CHECK") -> OK | D33: =IF(D32=D31,"OK","CHECK") -> OK

Sheet Sensitivity
A1: Sensitivity and stress cases
A2: Scenario C operating result, $ millions. Each assumption moves alone. Blue = input.
A3: Scenario C base operating result ($M) | B3: =Scenarios!$D$20 -> 0.29
A5: Assumption | B5: Type | C5: Base | D5: Worse case | E5: Better case | F5: Result, worse ($M) | G5: Result, better ($M) | H5: Swing ($M)
A6: Initiative revenue uplift (share of plan) | B6: Execution | C6: 1 | D6: 0.5 | E6: 1.5 | F6: =$B$3+(D6-C6)*Initiatives!$D$14 -> -1.035 | G6: =$B$3+(E6-C6)*Initiatives!$D$14 -> 1.615 | H6: =G6-F6 -> 2.65
A7: Cost savings realized (share of plan) | B7: Execution | C7: 1 | D7: 0.5 | E7: 1.5 | F7: =$B$3+(D7-C7)*Initiatives!$D$15 -> -0.41 | G7: =$B$3+(E7-C7)*Initiatives!$D$15 -> 0.99 | H7: =G7-F7 -> 1.4
A8: State Medicaid financing cut | B8: Policy | C8: =Inputs!$B$30 -> 0.06 | D8: 0.12 | E8: 0 | F8: =$B$3-(D8-C8)*Baseline!$C$25 -> -0.01 | G8: =$B$3-(E8-C8)*Baseline!$C$25 -> 0.59 | H8: =G8-F8 -> 0.6
A9: New program costs (share of plan) | B9: Execution | C9: 1 | D9: 1.2 | E9: 0.8 | F9: =$B$3-(D9-C9)*Initiatives!$D$16 -> -0.01 | G9: =$B$3-(E9-C9)*Initiatives!$D$16 -> 0.59 | H9: =G9-F9 -> 0.6
A10: Medicaid expansion disenrollment | B10: Policy | C10: =Inputs!$B$27 -> 0.18 | D10: 0.36 | E10: 0.09 | F10: =$B$3-(D10-C10)*Headwinds!$B$5 -> -0.025 | G10: =$B$3-(E10-C10)*Headwinds!$B$5 -> 0.4475 | H10: =G10-F10 -> 0.4725
A11: Marketplace attrition | B11: Policy | C11: =Inputs!$B$29 -> 0.25 | D11: 0.5 | E11: 0.125 | F11: =$B$3-(D11-C11)*Headwinds!$B$6 -> 0.053 | G11: =$B$3-(E11-C11)*Headwinds!$B$6 -> 0.4085 | H11: =G11-F11 -> 0.3555
A13: Total swing, execution assumptions ($M) | H13: =SUMIF($B$6:$B$11,"Execution",$H$6:$H$11) -> 4.65
A14: Total swing, federal policy assumptions ($M) | H14: =SUMIF($B$6:$B$11,"Policy",$H$6:$H$11) -> 1.428
A16: Stress case | B16: Operating revenue ($M) | C16: Operating expenses ($M) | D16: Result ($M) | E16: Margin | F16: Below REH trigger?
A17: Scenario C: initiatives deliver only part of their revenue | B17: =Scenarios!$D$12-(1-Inputs!$B$48)*Initiatives!$D$14 -> 30.465 | C17: =Scenarios!$D$18 -> 31.5 | D17: =B17-C17 -> -1.035 | E17: =D17/B17 -> -0.033973412 | F17: =IF(E17<Inputs!$B$47,"Breach","OK") -> Breach
A18: Scenario B: larger Medicare outpatient shift under REH | B18: =Scenarios!$C$12-Inputs!$B$34*(Inputs!$B$6+Inputs!$B$7)*(Inputs!$B$49-Inputs!$B$35) -> 26.14472 | C18: =Scenarios!$C$18 -> 26 | D18: =B18-C18 -> 0.14472 | E18: =D18/B18 -> 0.0055353433 | F18: =IF(E18<Inputs!$B$47,"Breach","OK") -> OK
A20: Margin by scenario (feeds the comparison chart) | B20: Case | C20: Margin
A21: A: Hold as CAH | B21: Base | C21: =Scenarios!B21 -> -0.077556623
A22: B: Convert to REH | B22: Base | C22: =Scenarios!C21 -> 0.030212607
A23: B: Convert to REH | B23: Stress | C23: =E18 -> 0.0055353433
A24: C: CAH transformation | B24: Base | C24: =Scenarios!D21 -> 0.0091223655
A25: C: CAH transformation | B25: Stress | C25: =E17 -> -0.033973412

Sheet AI_ROI
A1: AI tooling: cost against attributable benefit
A2: $ millions a year. Attribution shares are illustrative assumptions, not evidence.
A3: Low-case benefit realization | B3: 0.5
A4: High-case benefit realization | B4: 1.5
A6: AI tool | B6: Linked initiative | C6: Annual tooling cost ($M) | D6: Linked initiative gain ($M) | E6: Share attributable to AI | F6: Base benefit ($M) | G6: Low benefit ($M) | H6: High benefit ($M) | I6: Base return (x cost)
A7: Revenue-cycle and dispute-claim AI | B7: 4 | C7: =Initiatives!$G$8 -> 0.1 | D7: =Initiatives!$D$8 -> 0.35 | E7: 0.5 | F7: =D7*E7 -> 0.175 | G7: =F7*$B$3 -> 0.0875 | H7: =F7*$B$4 -> 0.2625 | I7: =F7/C7 -> 1.75
A8: Tele-ED decision support | B8: 2 | C8: =Initiatives!$G$6 -> 0.1 | D8: =Initiatives!$D$6 -> 0.5 | E8: 0.25 | F8: =D8*E8 -> 0.125 | G8: =F8*$B$3 -> 0.0625 | H8: =F8*$B$4 -> 0.1875 | I8: =F8/C8 -> 1.25
A9: Ambient clinic documentation | B9: 1 | C9: =Initiatives!$G$5 -> 0.1 | D9: =Initiatives!$D$5 -> 1.2 | E9: 0.1 | F9: =D9*E9 -> 0.12 | G9: =F9*$B$3 -> 0.06 | H9: =F9*$B$4 -> 0.18 | I9: =F9/C9 -> 1.2
A10: Total | C10: =SUM(C7:C9) -> 0.3 | F10: =SUM(F7:F9) -> 0.42 | G10: =SUM(G7:G9) -> 0.21 | H10: =SUM(H7:H9) -> 0.63 | I10: =F10/C10 -> 1.4
A12: Break-even benefit realization (tooling cost / base benefit) | B12: =C10/F10 -> 0.71428571
A13: Low-case return (x cost) | B13: =G10/C10 -> 0.7
A14: High-case return (x cost) | B14: =H10/C10 -> 2.1
A16: Supply-chain analytics (initiative 5) has no separate tooling budget and is excluded. Coverage-outreach benefit is on the Initiatives sheet.
